<robot name = "robot">
    <link name="Torso">
        <inertial>
            <origin xyz="0 0 2.25" rpy="0 0 0"/>
            <mass value="1" />
            <inertia ixx="100" ixy="0" ixz="0" iyy="100" iyz="0" izz="100" />
        </inertial>
        <visual>
            <origin xyz="0 0 2.25" rpy="0 0 0"/>
            <geometry>
                <box size="1.8 0.8 0.4" />
            </geometry>
            <material name="Cyan">
                <color rgba="0 1.0 1.0 1.0"/>
            </material>
        </visual>
        <collision>
            <origin xyz="0 0 2.25" rpy="0 0 0"/>
            <geometry>
                <box size="1.8 0.8 0.4" />
            </geometry>
        </collision>
    </link>
    <joint name="Torso_FrontLeg" type="revolute">
       <parent link="Torso"/>
       <child  link="FrontLeg"/>
       <origin rpy="0 0 0" xyz="-0.5 0 2" />
     <axis xyz="0 1 0"/>
       <limit effort="0.0" lower="-3.14159" upper="3.14159" velocity="0.0"/>
    </joint>
    <link name="FrontLeg">
        <inertial>
            <origin xyz="0 -0.5 0" rpy="0 0 0"/>
            <mass value="1" />
            <inertia ixx="100" ixy="0" ixz="0" iyy="100" iyz="0" izz="100" />
        </inertial>
        <visual>
            <origin xyz="0 -0.5 0" rpy="0 0 0"/>
            <geometry>
                <box size="0.2 0.2 0.5" />
            </geometry>
            <material name="Cyan">
                <color rgba="0 1.0 1.0 1.0"/>
            </material>
        </visual>
        <collision>
            <origin xyz="0 -0.5 0" rpy="0 0 0"/>
            <geometry>
                <box size="0.2 0.2 0.5" />
            </geometry>
        </collision>
    </link>
    <joint name="FrontLeg_LowerFrontLeg" type="revolute">
       <parent link="FrontLeg"/>
       <child  link="LowerFrontLeg"/>
       <origin rpy="0 0 0" xyz="0 -0.5 -0.25" />
     <axis xyz="0 1 0"/>
       <limit effort="0.0" lower="-3.14159" upper="3.14159" velocity="0.0"/>
    </joint>
    <link name="LowerFrontLeg">
        <inertial>
            <origin xyz="0 0 -0.25" rpy="0 0 0"/>
            <mass value="1" />
            <inertia ixx="100" ixy="0" ixz="0" iyy="100" iyz="0" izz="100" />
        </inertial>
        <visual>
            <origin xyz="0 0 -0.25" rpy="0 0 0"/>
            <geometry>
                <box size="0.2 0.2 0.5" />
            </geometry>
            <material name="Cyan">
                <color rgba="0 1.0 1.0 1.0"/>
            </material>
        </visual>
        <collision>
            <origin xyz="0 0 -0.25" rpy="0 0 0"/>
            <geometry>
                <box size="0.2 0.2 0.5" />
            </geometry>
        </collision>
    </link>
    <joint name="Torso_BackLeg" type="revolute">
       <parent link="Torso"/>
       <child  link="BackLeg"/>
       <origin rpy="0 0 0" xyz="0.5 0 2" />
     <axis xyz="0 1 0"/>
       <limit effort="0.0" lower="-3.14159" upper="3.14159" velocity="0.0"/>
    </joint>
    <link name="BackLeg">
        <inertial>
            <origin xyz="0 -0.5 0" rpy="0 0 0"/>
            <mass value="1" />
            <inertia ixx="100" ixy="0" ixz="0" iyy="100" iyz="0" izz="100" />
        </inertial>
        <visual>
            <origin xyz="0 -0.5 0" rpy="0 0 0"/>
            <geometry>
                <box size="0.2 0.2 0.5" />
            </geometry>
            <material name="Cyan">
                <color rgba="0 1.0 1.0 1.0"/>
            </material>
        </visual>
        <collision>
            <origin xyz="0 -0.5 0" rpy="0 0 0"/>
            <geometry>
                <box size="0.2 0.2 0.5" />
            </geometry>
        </collision>
    </link>
    <joint name="BackLeg_LowerBackLeg" type="revolute">
       <parent link="BackLeg"/>
       <child  link="LowerBackLeg"/>
       <origin rpy="0 0 0" xyz="0 -0.5 -0.2" />
     <axis xyz="0 1 0"/>
       <limit effort="0.0" lower="-3.14159" upper="3.14159" velocity="0.0"/>
    </joint>
    <link name="LowerBackLeg">
        <inertial>
            <origin xyz="0 0 -0.25" rpy="0 0 0"/>
            <mass value="1" />
            <inertia ixx="100" ixy="0" ixz="0" iyy="100" iyz="0" izz="100" />
        </inertial>
        <visual>
            <origin xyz="0 0 -0.25" rpy="0 0 0"/>
            <geometry>
                <box size="0.2 0.2 0.5" />
            </geometry>
            <material name="Cyan">
                <color rgba="0 1.0 1.0 1.0"/>
            </material>
        </visual>
        <collision>
            <origin xyz="0 0 -0.25" rpy="0 0 0"/>
            <geometry>
                <box size="0.2 0.2 0.5" />
            </geometry>
        </collision>
    </link>
    <joint name="Torso_LeftLeg" type="revolute">
       <parent link="Torso"/>
       <child  link="LeftLeg"/>
       <origin rpy="0 0 0" xyz="-0.5 0 2" />
     <axis xyz="0 1 0"/>
       <limit effort="0.0" lower="-3.14159" upper="3.14159" velocity="0.0"/>
    </joint>
    <link name="LeftLeg">
        <inertial>
            <origin xyz="0 0.5 0" rpy="0 0 0"/>
            <mass value="1" />
            <inertia ixx="100" ixy="0" ixz="0" iyy="100" iyz="0" izz="100" />
        </inertial>
        <visual>
            <origin xyz="0 0.5 0" rpy="0 0 0"/>
            <geometry>
                <box size="0.2 0.2 0.5" />
            </geometry>
            <material name="Cyan">
                <color rgba="0 1.0 1.0 1.0"/>
            </material>
        </visual>
        <collision>
            <origin xyz="0 0.5 0" rpy="0 0 0"/>
            <geometry>
                <box size="0.2 0.2 0.5" />
            </geometry>
        </collision>
    </link>
    <joint name="LeftLeg_LowerLeftLeg" type="revolute">
       <parent link="LeftLeg"/>
       <child  link="LowerLeftLeg"/>
       <origin rpy="0 0 0" xyz="0 0.5 -0.2" />
     <axis xyz="0 1 0"/>
       <limit effort="0.0" lower="-3.14159" upper="3.14159" velocity="0.0"/>
    </joint>
    <link name="LowerLeftLeg">
        <inertial>
            <origin xyz="0 0 -0.25" rpy="0 0 0"/>
            <mass value="1" />
            <inertia ixx="100" ixy="0" ixz="0" iyy="100" iyz="0" izz="100" />
        </inertial>
        <visual>
            <origin xyz="0 0 -0.25" rpy="0 0 0"/>
            <geometry>
                <box size="0.2 0.2 0.5" />
            </geometry>
            <material name="Cyan">
                <color rgba="0 1.0 1.0 1.0"/>
            </material>
        </visual>
        <collision>
            <origin xyz="0 0 -0.25" rpy="0 0 0"/>
            <geometry>
                <box size="0.2 0.2 0.5" />
            </geometry>
        </collision>
    </link>
    <joint name="Torso_RightLeg" type="revolute">
       <parent link="Torso"/>
       <child  link="RightLeg"/>
       <origin rpy="0 0 0" xyz="0.5 0 2" />
     <axis xyz="0 1 0"/>
       <limit effort="0.0" lower="-3.14159" upper="3.14159" velocity="0.0"/>
    </joint>
    <link name="RightLeg">
        <inertial>
            <origin xyz="0 0.5 0" rpy="0 0 0"/>
            <mass value="1" />
            <inertia ixx="100" ixy="0" ixz="0" iyy="100" iyz="0" izz="100" />
        </inertial>
        <visual>
            <origin xyz="0 0.5 0" rpy="0 0 0"/>
            <geometry>
                <box size="0.2 0.2 0.5" />
            </geometry>
            <material name="Cyan">
                <color rgba="0 1.0 1.0 1.0"/>
            </material>
        </visual>
        <collision>
            <origin xyz="0 0.5 0" rpy="0 0 0"/>
            <geometry>
                <box size="0.2 0.2 0.5" />
            </geometry>
        </collision>
    </link>
    <joint name="RightLeg_LowerRightLeg" type="revolute">
       <parent link="RightLeg"/>
       <child  link="LowerRightLeg"/>
       <origin rpy="0 0 0" xyz="0 0.5 -0.2" />
     <axis xyz="0 1 0"/>
       <limit effort="0.0" lower="-3.14159" upper="3.14159" velocity="0.0"/>
    </joint>
    <link name="LowerRightLeg">
        <inertial>
            <origin xyz="0 0 -0.25" rpy="0 0 0"/>
            <mass value="1" />
            <inertia ixx="100" ixy="0" ixz="0" iyy="100" iyz="0" izz="100" />
        </inertial>
        <visual>
            <origin xyz="0 0 -0.25" rpy="0 0 0"/>
            <geometry>
                <box size="0.2 0.2 0.5" />
            </geometry>
            <material name="Cyan">
                <color rgba="0 1.0 1.0 1.0"/>
            </material>
        </visual>
        <collision>
            <origin xyz="0 0 -0.25" rpy="0 0 0"/>
            <geometry>
                <box size="0.2 0.2 0.5" />
            </geometry>
        </collision>
    </link>
    <joint name="Torso_LowerArm" type="revolute">
       <parent link="Torso"/>
       <child  link="LowerArm"/>
       <origin rpy="0 0 0" xyz="-0.5 0 2.1" />
     <axis xyz="0 1 0"/>
       <limit effort="0.0" lower="-3.14159" upper="3.14159" velocity="0.0"/>
    </joint>
    <link name="LowerArm">
        <inertial>
            <origin xyz="0 0 0.4" rpy="0 0 0"/>
            <mass value="1" />
            <inertia ixx="100" ixy="0" ixz="0" iyy="100" iyz="0" izz="100" />
        </inertial>
        <visual>
            <origin xyz="0 0 0.4" rpy="0 0 0"/>
            <geometry>
                <box size="0.2 0.2 0.8" />
            </geometry>
            <material name="Cyan">
                <color rgba="0 1.0 1.0 1.0"/>
            </material>
        </visual>
        <collision>
            <origin xyz="0 0 0.4" rpy="0 0 0"/>
            <geometry>
                <box size="0.2 0.2 0.8" />
            </geometry>
        </collision>
    </link>
    <joint name="LowerArm_UpperArm" type="revolute">
       <parent link="LowerArm"/>
       <child  link="UpperArm"/>
       <origin rpy="0 0 0" xyz="0 0 0.8" />
     <axis xyz="0 1 0"/>
       <limit effort="0.0" lower="-3.14159" upper="3.14159" velocity="0.0"/>
    </joint>
    <link name="UpperArm">
        <inertial>
            <origin xyz="-0.4 0 0.1" rpy="0 0 0"/>
            <mass value="1" />
            <inertia ixx="100" ixy="0" ixz="0" iyy="100" iyz="0" izz="100" />
        </inertial>
        <visual>
            <origin xyz="-0.4 0 0.1" rpy="0 0 0"/>
            <geometry>
                <box size="0.8 0.2 0.2" />
            </geometry>
            <material name="Cyan">
                <color rgba="0 1.0 1.0 1.0"/>
            </material>
        </visual>
        <collision>
            <origin xyz="-0.4 0 0.1" rpy="0 0 0"/>
            <geometry>
                <box size="0.8 0.2 0.2" />
            </geometry>
        </collision>
    </link>
    <joint name="UpperArm_TopFinger" type="revolute">
       <parent link="UpperArm"/>
       <child  link="TopFinger"/>
       <origin rpy="0 0 0" xyz="-0.8 0 0.1" />
     <axis xyz="0 1 0"/>
       <limit effort="0.0" lower="-3.14159" upper="3.14159" velocity="0.0"/>
    </joint>
    <link name="TopFinger">
        <inertial>
            <origin xyz="-0.2 0 0.1" rpy="0 0 0"/>
            <mass value="1" />
            <inertia ixx="100" ixy="0" ixz="0" iyy="100" iyz="0" izz="100" />
        </inertial>
        <visual>
            <origin xyz="-0.2 0 0.1" rpy="0 0 0"/>
            <geometry>
                <box size="0.4 0.2 0.1" />
            </geometry>
            <material name="Cyan">
                <color rgba="0 1.0 1.0 1.0"/>
            </material>
        </visual>
        <collision>
            <origin xyz="-0.2 0 0.1" rpy="0 0 0"/>
            <geometry>
                <box size="0.4 0.2 0.1" />
            </geometry>
        </collision>
    </link>
    <joint name="UpperArm_BottomFinger" type="revolute">
       <parent link="UpperArm"/>
       <child  link="BottomFinger"/>
       <origin rpy="0 0 0" xyz="-0.8 0 -0.1" />
     <axis xyz="0 1 0"/>
       <limit effort="0.0" lower="-3.14159" upper="3.14159" velocity="0.0"/>
    </joint>
    <link name="BottomFinger">
        <inertial>
            <origin xyz="-0.2 0 0.1" rpy="0 0 0"/>
            <mass value="1" />
            <inertia ixx="100" ixy="0" ixz="0" iyy="100" iyz="0" izz="100" />
        </inertial>
        <visual>
            <origin xyz="-0.2 0 0.1" rpy="0 0 0"/>
            <geometry>
                <box size="0.4 0.2 0.1" />
            </geometry>
            <material name="Cyan">
                <color rgba="0 1.0 1.0 1.0"/>
            </material>
        </visual>
        <collision>
            <origin xyz="-0.2 0 0.1" rpy="0 0 0"/>
            <geometry>
                <box size="0.4 0.2 0.1" />
            </geometry>
        </collision>
    </link>
</robot>